2025-07-22 11:25:22,876 - celery.utils.functional - DEBUG - 
def chord(self, header, body, partial_args=0, interval=1, countdown=2, max_retries=3, eager=4, **kwargs):
    return 1

2025-07-22 11:25:22,877 - celery.utils.functional - DEBUG - 
def chunks(task, it, n):
    return 1

2025-07-22 11:25:22,877 - celery.utils.functional - DEBUG - 
def unlock_chord(self, group_id, callback, interval=0, max_retries=1, result=2, Result=3, GroupResult=4, result_from_tuple=5, **kwargs):
    return 1

2025-07-22 11:25:22,878 - celery.utils.functional - DEBUG - 
def group(self, tasks, result, group_id, partial_args, add_to_parent=0):
    return 1

2025-07-22 11:25:22,879 - celery.utils.functional - DEBUG - 
def xmap(task, it):
    return 1

2025-07-22 11:25:22,880 - celery.utils.functional - DEBUG - 
def procesar_archivo_task(self, file_path, user_id):
    return 1

2025-07-22 11:25:22,881 - celery.utils.functional - DEBUG - 
def backend_cleanup():
    return 1

2025-07-22 11:25:22,881 - celery.utils.functional - DEBUG - 
def chain(*args, **kwargs):
    return 1

2025-07-22 11:25:22,882 - celery.utils.functional - DEBUG - 
def xstarmap(task, it):
    return 1

2025-07-22 11:25:22,882 - celery.utils.functional - DEBUG - 
def accumulate(self, *args, **kwargs):
    return 1

2025-07-22 11:25:31,694 - waitress - INFO - Serving on http://0.0.0.0:5001
2025-07-22 11:25:46,781 - __main__ - INFO - Conexión establecida correctamente con pymysql a 127.0.0.1.
2025-07-22 11:25:46,984 - __main__ - INFO - Conexión establecida correctamente con pymysql a 127.0.0.1.
2025-07-22 11:25:46,994 - app - ERROR - Exception on / [GET]
Traceback (most recent call last):
  File "C:\Users\Administrator\AppData\Local\Programs\Python\Python313\Lib\site-packages\flask\app.py", line 1511, in wsgi_app
    response = self.full_dispatch_request()
  File "C:\Users\Administrator\AppData\Local\Programs\Python\Python313\Lib\site-packages\flask\app.py", line 919, in full_dispatch_request
    rv = self.handle_user_exception(e)
  File "C:\Users\Administrator\AppData\Local\Programs\Python\Python313\Lib\site-packages\flask\app.py", line 917, in full_dispatch_request
    rv = self.dispatch_request()
  File "C:\Users\Administrator\AppData\Local\Programs\Python\Python313\Lib\site-packages\flask\app.py", line 902, in dispatch_request
    return self.ensure_sync(self.view_functions[rule.endpoint])(**view_args)  # type: ignore[no-any-return]
           ~~~~~~~~~~~~~~~~~~~~~~~~~~~~~~~~~~~~~~~~~~~~~~~~~~~~^^^^^^^^^^^^^
  File "C:\Users\Administrator\AppData\Local\Programs\Python\Python313\Lib\site-packages\flask_login\utils.py", line 290, in decorated_view
    return current_app.ensure_sync(func)(*args, **kwargs)
           ~~~~~~~~~~~~~~~~~~~~~~~~~~~~~^^^^^^^^^^^^^^^^^
  File "C:\Coordenadas Mejorado\app.py", line 635, in index
    return render_template("index.html")
  File "C:\Users\Administrator\AppData\Local\Programs\Python\Python313\Lib\site-packages\flask\templating.py", line 150, in render_template
    return _render(app, template, context)
  File "C:\Users\Administrator\AppData\Local\Programs\Python\Python313\Lib\site-packages\flask\templating.py", line 131, in _render
    rv = template.render(context)
  File "C:\Users\Administrator\AppData\Local\Programs\Python\Python313\Lib\site-packages\jinja2\environment.py", line 1295, in render
    self.environment.handle_exception()
    ~~~~~~~~~~~~~~~~~~~~~~~~~~~~~~~~~^^
  File "C:\Users\Administrator\AppData\Local\Programs\Python\Python313\Lib\site-packages\jinja2\environment.py", line 942, in handle_exception
    raise rewrite_traceback_stack(source=source)
  File "C:\Coordenadas Mejorado\templates\index.html", line 147, in top-level template code
    <a class="nav-link" href="{{ url_for('switch_bp.switch_analysis') }}">Validación Switch</a>
    ^
  File "C:\Users\Administrator\AppData\Local\Programs\Python\Python313\Lib\site-packages\flask\app.py", line 1121, in url_for
    return self.handle_url_build_error(error, endpoint, values)
           ~~~~~~~~~~~~~~~~~~~~~~~~~~~^^^^^^^^^^^^^^^^^^^^^^^^^
  File "C:\Users\Administrator\AppData\Local\Programs\Python\Python313\Lib\site-packages\flask\app.py", line 1110, in url_for
    rv = url_adapter.build(  # type: ignore[union-attr]
        endpoint,
    ...<3 lines>...
        force_external=_external,
    )
  File "C:\Users\Administrator\AppData\Local\Programs\Python\Python313\Lib\site-packages\werkzeug\routing\map.py", line 924, in build
    raise BuildError(endpoint, values, method, self)
werkzeug.routing.exceptions.BuildError: Could not build url for endpoint 'switch_bp.switch_analysis'. Did you mean 'static' instead?
